Workbook
Name GRAND: 'CO 703'!#REF!
Name GRAND: 'G703'!#REF!
Name Print_Area_MI: 'CO 703'!$B$12:$K$38
Name Print_Area_MI: 'G703'!$B$12:$K$30
Name Print_Area_MI: 'G702'!$A$1:$O$54
Name Print_Titles_MI: 'CO 703'!$1:$11
Name Print_Titles_MI: 'G703'!$1:$11
Name Print_Titles_MI: 'G702'!$67:$374,'G702'!$B$1:$O$16383

Sheet G702
A1: APPLICATION AND CERTIFICATION FOR PAYMENT | H1: AIA DOCUMENT G702 | K1: PAGE 1 OF | L1: 3
A3: TO CONTRACTOR: | E3: PROJECT: | F3: Hunters Landing | I3: APPLICATION #: | J3: 13 | L3: Distribution to:
A5: Makers Line | I5: Invoice #14702 | M5: OWNER
A7: 537 W 600 S, Ste 400 | M7: ARCHITECT
A9: Salt Lake City, UT 84101 | I9: PERIOD TO: | J9: 45016 | L9: X | M9: CONTRACTOR
A11: FROM SUB-CONTRACTOR: | E11: VIA ARCHITECT: | M11: CONST. MGR.
A13: B&M Plumbing & Heating | M13: Lender
A15: PO Box 1374 | I15: PROJECT #: | J15: 21-10004
A16: Riverton, UT 84065
A17: CONTRACT FOR: | I17: CONTRACT DATE: | J17: 44638
A19: CONTRACTOR'S APPLICATION FOR PAYMENT | H19: The undersigned Contractor certifies that to the best of the Contractor's knowledge,
A20: Application is made for payment, as shown below, in connection with the Contract. | H20: information and belief the Work covered by this Application for Payment has been
A21: Continuation Sheet, AIA Document G703, is attached. | H21: completed in accordance with the Contract Documents, that all amounts have been paid by
H22: the Contractor for Work for which previous Certificates for Payment were issued and
H23: payments received from the Owner, and that current payment shown herein is now due.
A25: 1. ORIGINAL CONTRACT SUM | E25: $ | F25: ='G703'!D29 -> 1638000
A26: 2. NET CHANGE BY CHANGE ORDERS | E26: $ | F26: ='CO 703'!D37 -> -114343.5 | H26: CONTRACTOR:
A27: 3. CONTRACT SUM TO DATE | E27: $ | F27: =ROUND(SUM(F25:F26),2) -> 1523656.5
A28: 4. TOTAL COMPLETED & STORED TO DATE (Column G on G703) | E28: $ | F28: ='G703'!H29+'CO 703'!H37 -> 1380624.5
H29: By: | L29: Date:
A31: 5. RETAINAGE: | H31: State of: | K31: County of:
B32: ='G703'!K11 -> 0.05 | C32: (Column K on G703) | D32: of Completed Work $ | E32: ='G703'!K29+'CO 703'!K37 -> 69031.23 | H32: Subscribed and sworn to before me this | K32: day of
H33: Notary Public:
H34: My Commission expires:
A35: 6. TOTAL EARNED LESS RETAINAGE | E35: $ | F35: =ROUND(SUM(F28-E32),2) -> 1311593.3
H36: ARCHITECT'S CERTIFICATE FOR PAYMENT
H37: In accordance with the Contract Documents, based on on-site observations and the data
A38: 7. LESS PREVIOUS CERTIFICATES FOR PAYMENT (Line 6 from prior Certificate) | E38: $ | F38: 1249349.3 | H38: comprising the application, the Architect certifies to the Owner that to the best of the
A39: 8. CURRENT PAYMENT DUE | E39: $ | F39: =ROUND(SUM(F35-F38),2) -> 62244 | H39: Architect's knowledge, information and belief the Work has progressed as indicated,
A40: 9. BALANCE TO FINISH, INCLUDING RETAINAGE | E40: $ | F40: =ROUND(SUM(F27-F35),2) -> 212063.23 | H40: the quality of the Work is in accordance with the Contract Documents, and the Contractor
H41: is entitled to payment of the AMOUNT CERTIFIED.
H43: AMOUNT CERTIFIED . . . . . . . . .. . . . . .$ | K43: =F39 -> 62244
A45: CHANGE ORDER SUMMARY | E45: ADDITIONS | F45: DEDUCTIONS | H45: (Attach explanation if amount certified differs from the amount applied. Initial all figures on this
A46: Total changes approved in previous months | E46: 0 | F46: 0 | H46: Application and onthe Continuation Sheet that are changed to conform with the amount certified.)
H47: ARCHITECT:
A48: Total approved this Month | E48: 0 | F48: 0 | H48: By: | L48: Date:
E49: =SUM(E46:E48) -> 0 | F49: =F46+F48 -> 0
A50: TOTALS | H50: This Certificate is not negotiable. The AMOUNT CERTIFIED is payable only to the
H51: Contractor named herein. Issuance, payment and acceptance of payment are without
A52: NET CHANGES by Change Order | E52: =E49-F49 -> 0 | H52: prejudice to any rights of the Owner or Contractor under this Contract.
...

Sheet G703
B1: CONTINUATION SHEET | F1: AIA DOCUMENT G703 | J1: PAGE 2 | II1: /WGPD
B2: AIA Document G702, APPLICATION AND CERTIFICATION FOR PAYMENT, containing | I2: APPLICATION #: | J2: 13 | II2: /wir.{d 25}~{r 6}/cf~~{L 6}~
B3: Contractor's signed certification is attached. | I3: APPLICATION DATE: | J3: 45000 | II3: /wgpe
B4: In tabulations below, amounts are stated to the nearest dollar. | I4: PERIOD TO: | J4: ='G702'!J9 -> 45016 | II4: /ru.{d 26}
B5: Use Column I on Contracts where variable retainage for line items may apply. | I5: ARCHITECT'S PROJECT #: | J5: ='G702'!J15 -> 21-10004 | II5: {L 5}
II6: {L 9}
B7: A | C7: B | D7: C | E7: D | F7: E | G7: F | H7: G | J7: H | K7: I | II7: /ru.{d 26}~
B8: ITEM | C8: DESCRIPTION OF WORK | D8: SCHEDULED | E8: WORK COMPLETED | G8: MATERIALS | H8: TOTAL | I8: % | J8: BALANCE | K8: RETAINAGE
B9: # | D9: VALUE | E9: FROM PREVIOUS | F9: THIS PERIOD | G9: PRESENTLY | H9: COMPLETED | I9: COMPLETE | J9: TO FINISH
E10: APPLICATION | G10: STORED | H10: AND STORED
H11: TO DATE | K11: 0.05
B12: 1 | C12: 22-0050 - Plumbing April | D12: 49140 | E12: 49140 | H12: =ROUND(SUM(E12+F12+G12),2) -> 49140 | I12: =H12/D12 -> 1 | J12: =ROUND(SUM(D12-H12),2) -> 0 | K12: =ROUND(SUM(H12*$K$11),2) -> 2457
B13: 2 | C13: 22-0050 - Plumbing May | D13: 49140 | E13: 49140 | H13: =ROUND(SUM(E13+F13+G13),2) -> 49140 | I13: =H13/D13 -> 1 | J13: =ROUND(SUM(D13-H13),2) -> 0 | K13: =ROUND(SUM(H13*$K$11),2) -> 2457
B14: 3 | C14: 22-0050 - Plumbing June | D14: 103800 | E14: 103800 | H14: =ROUND(SUM(E14+F14+G14),2) -> 103800 | I14: =H14/D14 -> 1 | J14: =ROUND(SUM(D14-H14),2) -> 0 | K14: =ROUND(SUM(H14*$K$11),2) -> 5190
B15: 4 | C15: 22-0050 - Plumbing July | D15: 163800 | E15: 163800 | H15: =ROUND(SUM(E15+F15+G15),2) -> 163800 | I15: =H15/D15 -> 1 | J15: =ROUND(SUM(D15-H15),2) -> 0 | K15: =ROUND(SUM(H15*$K$11),2) -> 8190
B16: 5 | C16: 22-0050 - Plumbing August | D16: 163800 | E16: 163800 | H16: =ROUND(SUM(E16+F16+G16),2) -> 163800 | I16: =H16/D16 -> 1 | J16: =ROUND(SUM(D16-H16),2) -> 0 | K16: =ROUND(SUM(H16*$K$11),2) -> 8190
B17: 6 | C17: 22-0050 - Plumbing September | D17: 163800 | E17: 163800 | H17: =ROUND(SUM(E17+F17+G17),2) -> 163800 | I17: =H17/D17 -> 1 | J17: =ROUND(SUM(D17-H17),2) -> 0 | K17: =ROUND(SUM(H17*$K$11),2) -> 8190
B18: 7 | C18: 22-0050 - Plumbing October | D18: 163800 | E18: 163800 | H18: =ROUND(SUM(E18+F18+G18),2) -> 163800 | I18: =H18/D18 -> 1 | J18: =ROUND(SUM(D18-H18),2) -> 0 | K18: =ROUND(SUM(H18*$K$11),2) -> 8190
B19: 8 | C19: 22-0050 - Plumbing November | D19: 163800 | E19: 163800 | H19: =ROUND(SUM(E19+F19+G19),2) -> 163800 | I19: =H19/D19 -> 1 | J19: =ROUND(SUM(D19-H19),2) -> 0 | K19: =ROUND(SUM(H19*$K$11),2) -> 8190
C20: 22-0050 Plumbing November extra | D20: 13192 | E20: 13192 | H20: =ROUND(SUM(E20+F20+G20),2) -> 13192 | I20: =H20/D20 -> 1 | J20: =ROUND(SUM(D20-H20),2) -> 0 | K20: =ROUND(SUM(H20*$K$11),2) -> 659.6
B21: 9 | C21: 22-0050 - Plumbing December | D21: 163800 | E21: 163800 | H21: =ROUND(SUM(E21+F21+G21),2) -> 163800 | I21: =H21/D21 -> 1 | J21: =ROUND(SUM(D21-H21),2) -> 0 | K21: =ROUND(SUM(H21*$K$11),2) -> 8190
B22: 10 | C22: 22-0050 - Plumbing January | D22: 65520 | E22: 65520 | H22: =ROUND(SUM(E22+F22+G22),2) -> 65520 | I22: =H22/D22 -> 1 | J22: =ROUND(SUM(D22-H22),2) -> 0 | K22: =ROUND(SUM(H22*$K$11),2) -> 3276
B23: 11 | C23: 22-0050 - Plumbing February | D23: 65520 | E23: 65520 | H23: =ROUND(SUM(E23+F23+G23),2) -> 65520 | I23: =H23/D23 -> 1 | J23: =ROUND(SUM(D23-H23),2) -> 0 | K23: =ROUND(SUM(H23*$K$11),2) -> 3276
B24: 12 | C24: 22-0050 - Plumbing March | D24: 65520 | F24: 65520 | H24: =ROUND(SUM(E24+F24+G24),2) -> 65520 | I24: =H24/D24 -> 1 | J24: =ROUND(SUM(D24-H24),2) -> 0 | K24: =ROUND(SUM(H24*$K$11),2) -> 3276
C25: April | D25: 65520 | H25: =ROUND(SUM(E25+F25+G25),2) -> 0 | I25: =H25/D25 -> 0 | J25: 65520 | K25: =ROUND(SUM(H25*$K$11),2) -> 0
C26: May | D26: 65520 | H26: =ROUND(SUM(E26+F26+G26),2) -> 0 | I26: =H26/D26 -> 0 | J26: 65520 | K26: =ROUND(SUM(H26*$K$11),2) -> 0
C27: June | D27: 65520 | H27: =ROUND(SUM(E27+F27+G27),2) -> 0 | I27: =H27/D27 -> 0 | J27: 65520 | K27: =ROUND(SUM(H27*$K$11),2) -> 0
B28: 13 | C28: 22-0050 - Plumbing July | D28: 46808 | H28: =ROUND(SUM(E28+F28+G28),2) -> 0 | I28: =H28/D28 -> 0 | J28: =ROUND(SUM(D28-H28),2) -> 46808 | K28: =ROUND(SUM(H28*$K$11),2) -> 0
C29: TOTALS | D29: =ROUND(SUM(D12:D28),2) -> 1638000 | E29: =ROUND(SUM(E12:E28),2) -> 1329112 | F29: =ROUND(SUM(F12:F28),2) -> 65520 | G29: =ROUND(SUM(G12:G28),2) -> 0 | H29: =ROUND(SUM(E29+F29+G29),2) -> 1394632 | I29: =H29/D29 -> 0.85142369 | J29: =ROUND(SUM(J12:J28),2) -> 243368 | K29: =ROUND(SUM(K12:K28),2) -> 69731.6

Sheet CO 703
B1: CONTINUATION SHEET | F1: AIA DOCUMENT G703 | J1: PAGE 3 | II1: /WGPD
B2: AIA Document G702, APPLICATION AND CERTIFICATION FOR PAYMENT, containing | I2: APPLICATION NO: | J2: ='G702'!J3 -> 13 | II2: /wir.{d 25}~{r 6}/cf~~{L 6}~
B3: Contractor's signed certification is attached. | I3: APPLICATION DATE: | II3: /wgpe
B4: In tabulations below, amounts are stated to the nearest dollar. | I4: PERIOD TO: | J4: ='G702'!J9 -> 45016 | II4: /ru.{d 26}
B5: Use Column I on Contracts where variable retainage for line items may apply. | I5: ARCHITECT'S PROJECT NO: | J5: ='G702'!J15 -> 21-10004 | II5: {L 5}
II6: {L 9}
B7: A | C7: B | D7: C | E7: D | F7: E | G7: F | H7: G | J7: H | K7: I | II7: /ru.{d 26}~
B8: ITEM | C8: DESCRIPTION OF WORK | D8: CHANGE ORDER AMOUNT | E8: WORK COMPLETED | G8: MATERIALS | H8: TOTAL | I8: % | J8: BALANCE | K8: RETAINAGE
B9: # | E9: FROM PREVIOUS | F9: THIS PERIOD | G9: PRESENTLY | H9: COMPLETED | I9: COMPLETE | J9: TO FINISH
E10: APPLICATION | G10: STORED | H10: AND STORED
H11: TO DATE | K11: 0.05
B12: 1 | C12: Change Orders | D12: -83925 | E12: -16784 | H12: =ROUND(SUM(E12+F12+G12),2) -> -16784 | I12: =H12/D12 -> 0.19998808 | J12: =ROUND(SUM(D12-H12),2) -> -67141 | K12: =ROUND(SUM(H12*$K$11),2) -> -839.2
B13: 2 | C13: Change Order Gas Line | D13: -48000 | E13: -9600 | H13: =ROUND(SUM(E13+F13+G13),2) -> -9600 | I13: =H13/D13 -> 0.2 | J13: =ROUND(SUM(D13-H13),2) -> -38400 | K13: =ROUND(SUM(H13*$K$11),2) -> -480
B14: 3 | C14: Change order roof drains | D14: 12376.5 | E14: 12376.5 | H14: =ROUND(SUM(E14+F14+G14),2) -> 12376.5 | I14: =H14/D14 -> 1 | J14: =ROUND(SUM(D14-H14),2) -> 0 | K14: =ROUND(SUM(H14*$K$11),2) -> 618.83
B15: 4 | C15: #8 change order | D15: 5205 | H15: =ROUND(SUM(E15+F15+G15),2) -> 0 | I15: =H15/D15 -> 0 | J15: =ROUND(SUM(D15-H15),2) -> 5205 | K15: =ROUND(SUM(H15*$K$11),2) -> 0
B16: 5 | H16: =ROUND(SUM(E16+F16+G16),2) -> 0 | I16: =H16/D16 -> #DIV/0! | J16: =ROUND(SUM(D16-H16),2) -> 0 | K16: =ROUND(SUM(H16*$K$11),2) -> 0
B17: 6 | H17: =ROUND(SUM(E17+F17+G17),2) -> 0 | I17: =H17/D17 -> #DIV/0! | J17: =ROUND(SUM(D17-H17),2) -> 0 | K17: =ROUND(SUM(H17*$K$11),2) -> 0
B18: 7 | H18: =ROUND(SUM(E18+F18+G18),2) -> 0 | I18: =H18/D18 -> #DIV/0! | J18: =ROUND(SUM(D18-H18),2) -> 0 | K18: =ROUND(SUM(H18*$K$11),2) -> 0
B19: 8 | H19: =ROUND(SUM(E19+F19+G19),2) -> 0 | I19: =H19/D19 -> #DIV/0! | J19: =ROUND(SUM(D19-H19),2) -> 0 | K19: =ROUND(SUM(H19*$K$11),2) -> 0
B20: 9 | H20: =ROUND(SUM(E20+F20+G20),2) -> 0 | I20: =H20/D20 -> #DIV/0! | J20: =ROUND(SUM(D20-H20),2) -> 0 | K20: =ROUND(SUM(H20*$K$11),2) -> 0
B21: 10 | H21: =ROUND(SUM(E21+F21+G21),2) -> 0 | I21: =H21/D21 -> #DIV/0! | J21: =ROUND(SUM(D21-H21),2) -> 0 | K21: =ROUND(SUM(H21*$K$11),2) -> 0
B22: 11 | H22: =ROUND(SUM(E22+F22+G22),2) -> 0 | I22: =H22/D22 -> #DIV/0! | J22: =ROUND(SUM(D22-H22),2) -> 0 | K22: =ROUND(SUM(H22*$K$11),2) -> 0
B23: 12 | H23: =ROUND(SUM(E23+F23+G23),2) -> 0 | I23: =H23/D23 -> #DIV/0! | J23: =ROUND(SUM(D23-H23),2) -> 0 | K23: =ROUND(SUM(H23*$K$11),2) -> 0
B24: 13 | H24: =ROUND(SUM(E24+F24+G24),2) -> 0 | I24: =H24/D24 -> #DIV/0! | J24: =ROUND(SUM(D24-H24),2) -> 0 | K24: =ROUND(SUM(H24*$K$11),2) -> 0
B25: 14 | H25: =ROUND(SUM(E25+F25+G25),2) -> 0 | I25: =H25/D25 -> #DIV/0! | J25: =ROUND(SUM(D25-H25),2) -> 0 | K25: =ROUND(SUM(H25*$K$11),2) -> 0
B26: 15 | H26: =ROUND(SUM(E26+F26+G26),2) -> 0 | I26: =H26/D26 -> #DIV/0! | J26: =ROUND(SUM(D26-H26),2) -> 0 | K26: =ROUND(SUM(H26*$K$11),2) -> 0
B27: 16 | H27: =ROUND(SUM(E27+F27+G27),2) -> 0 | I27: =H27/D27 -> #DIV/0! | J27: =ROUND(SUM(D27-H27),2) -> 0 | K27: =ROUND(SUM(H27*$K$11),2) -> 0
... B36: 25 | H36: =ROUND(SUM(E36+F36+G36),2) -> 0 | I36: =H36/D36 -> #DIV/0! | J36: =ROUND(SUM(D36-H36),2) -> 0 | K36: =ROUND(SUM(H36*$K$11),2) -> 0
C37: TOTALS | D37: =ROUND(SUM(D12:D36),2) -> -114343.5 | E37: =ROUND(SUM(E12:E36),2) -> -14007.5 | F37: =ROUND(SUM(F12:F36),2) -> 0 | G37: =ROUND(SUM(G12:G36),2) -> 0 | H37: =ROUND(SUM(H12:H36),2) -> -14007.5 | I37: =H37/D37 -> 0.12250368 | J37: =ROUND(SUM(J12:J36),2) -> -100336 | K37: =ROUND(SUM(K12:K36),2) -> -700.37
C40: Grand Total
C41: Grand Total | D41: =SUM(D37+'G703'!D29) -> 1523656.5 | E41: =SUM(E37+'G703'!E29) -> 1315104.5 | F41: =SUM(F37+'G703'!F29) -> 65520 | G41: =SUM(G37+'G703'!G29) -> 0 | H41: =SUM(H37+'G703'!H29) -> 1380624.5 | I41: =H41/D41 -> 0.90612582 | J41: =SUM(J37+'G703'!J29) -> 143032 | K41: =SUM(K37+'G703'!K29) -> 69031.23
