Workbook

Sheet Product List
A2: ABATEMENT/REMEDIATION/ASBESTOS | B2: 01u6S000018BAIdQAO | C2: 01t6S00000BhEQIQA3
A3: ADU | B3: 01u6S00001842qmQAA | C3: 01t6S00000BGzOMQA1
A4: APPLIANCES | B4: 01u6S000016ZYr8QAG | C4: 01t6S00000BGmgVQAT
A5: ARCHITECTURAL AND ENGINEERING | B5: 01u6S000016ZYrpQAG | C5: 01t6S00000BGmgXQAT
A6: BATHROOM | B6: 01u6S000018BAIeQAO | C6: 01t6S00000BhEQJQA3
A7: BUILDING CLEAN-UP | B7: 01u6S000016ZYroQAG | C7: 01t6S00000BGmhEQAT
A8: CABINETS | B8: 01u6S000016ZYrnQAG | C8: 01t6S00000BGmgUQAT
A9: COMPLETION AND INSPECTION | B9: 01u6S000016ZYrlQAG | C9: 01t6S00000BGmggQAD
A10: CONCRETE | B10: 01u6S000016ZYrkQAG | C10: 01t6S00000BGmgxQAD
A11: CONCRETE SUBFLOOR | B11: 01u6S00001844JrQAI | C11: 01t6S00000BH1bXQAT
A12: CONCRETE WALL | B12: 01u6S00001844JsQAI | C12: 01t6S00000BH1bTQAT
A13: CONTINGENCY | B13: 01u6S000016ZYrjQAG | C13: 01t6S00000BGmgfQAD
... A97: WINDOWS AND DOORS | B97: 01u6S000016ZYs5QAG | C97: 01t6S00000BGmh6QAD

Sheet Arixa SOV
A1: Price Book Entry ID | B1: Product ID | C1: Product DO NOT MAP | D1: Opportunity ID
A2: =IFERROR(VLOOKUP(C2,'Product List'!$A$2:$C198,2,FALSE),"") | B2: =IFERROR(VLOOKUP(C2,'Product List'!$A$2:$C198,3,FALSE),"")
A3: =IFERROR(VLOOKUP(C3,'Product List'!$A$2:$C198,2,FALSE),"") | B3: =IFERROR(VLOOKUP(C3,'Product List'!$A$2:$C198,3,FALSE),"")
A4: =IFERROR(VLOOKUP(C4,'Product List'!$A$2:$C198,2,FALSE),"") | B4: =IFERROR(VLOOKUP(C4,'Product List'!$A$2:$C198,3,FALSE),"")
A5: =IFERROR(VLOOKUP(C5,'Product List'!$A$2:$C198,2,FALSE),"") | B5: =IFERROR(VLOOKUP(C5,'Product List'!$A$2:$C198,3,FALSE),"")
A6: =IFERROR(VLOOKUP(C6,'Product List'!$A$2:$C198,2,FALSE),"") | B6: =IFERROR(VLOOKUP(C6,'Product List'!$A$2:$C198,3,FALSE),"") | F6: Property Address: | G6: 1075 Century Drive, Ogden, UT 84404 | S6: Construction Loan Amount: | T6: =G190 -> 16921419 | W6: Expected Completion Date:
A7: =IFERROR(VLOOKUP(C7,'Product List'!$A$2:$C198,2,FALSE),"") | B7: =IFERROR(VLOOKUP(C7,'Product List'!$A$2:$C198,3,FALSE),"") | F7: Borrower Name: | G7: Hunter's Landing North, LLC - Aubrey Palmer (PALMER AUBREY) | O7: Phone: | P7: (801) 400-8452 | S7: Remaining Balance Post Draw: | T7: =N190 -> 11494705 | W7: Draw Reimbursement % | Y7: 1
A8: =IFERROR(VLOOKUP(C8,'Product List'!$A$2:$C198,2,FALSE),"") | B8: =IFERROR(VLOOKUP(C8,'Product List'!$A$2:$C198,3,FALSE),"") | F8: Draw Point Of Contact | G8: - | O8: Phone: | S8: Lock Box | W8: Draw Fee Adjusted: | Y8: =SUM(T10/Y7) -> 500
A9: =IFERROR(VLOOKUP(C9,'Product List'!$A$2:$C198,2,FALSE),"") | B9: =IFERROR(VLOOKUP(C9,'Product List'!$A$2:$C198,3,FALSE),"") | F9: General Contractor: | O9: License: | S9: Project Square Footage | T9: 82227
A10: =IFERROR(VLOOKUP(C10,'Product List'!$A$2:$C198,2,FALSE),"") | B10: =IFERROR(VLOOKUP(C10,'Product List'!$A$2:$C198,3,FALSE),"") | F10: Inspectors Name: | O10: Phone: | S10: Draw Processing Fee: | T10: 500
A11: =IFERROR(VLOOKUP(C11,'Product List'!$A$2:$C198,2,FALSE),"") | B11: =IFERROR(VLOOKUP(C11,'Product List'!$A$2:$C198,3,FALSE),"")
A12: =IFERROR(VLOOKUP(C12,'Product List'!$A$2:$C198,2,FALSE),"") | B12: =IFERROR(VLOOKUP(C12,'Product List'!$A$2:$C198,3,FALSE),"")
A13: =IFERROR(VLOOKUP(C13,'Product List'!$A$2:$C198,2,FALSE),"") | B13: =IFERROR(VLOOKUP(C13,'Product List'!$A$2:$C198,3,FALSE),"") | E13: Item | F13: Description | G13: Budget | H13: Pre-Funding | I13: Approved | J13: Reallocation | K13: Revised Ready for Draw 1 | L13: % | M13: $ PSF | N13: Balance | O13: Draw #1 | P13: Draw #2 | Q13: Draw #3 | R13: Draw #4 | S13: Draw #5 | T13: Draw #6 | U13: Draw #7 | V13: Draw #8 | W13: Draw #9 | X13: Draw #10 | Y13: Draw #11 | Z13: Draw #12 | AA13: Draw #13 | AB13: Draw #14 | AC13: Draw #15 | AD13: Draw #16 | AE13: Draw #17 | AF13: Draw #18 | AG13: Draw #19 | AH13: Draw #20 | AI13: Draw #21 | AJ13: Draw #22 | AK13: Draw #23 | AL13: Retainage | AM13: Costs-to-Date | AN13: %
A14: =IFERROR(VLOOKUP(C14,'Product List'!$A$2:$C198,2,FALSE),"") | B14: =IFERROR(VLOOKUP(C14,'Product List'!$A$2:$C198,3,FALSE),"") | E14: # | G14: Amount | H14: Costs-to-Date & Contributed costs | I14: Current | J14: (+/-) | K14: Budget | L14: Of | M14: Of | N14: Remaining | O14: Amount(s) | P14: Amount(s) | Q14: Amount(s) | R14: Amount(s) | S14: Amount(s) | T14: Amount(s) | U14: Amount(s) | V14: Amount(s) | W14: Amount(s) | X14: Amount(s) | Y14: Amount(s) | Z14: Amount(s) | AA14: Amount(s) | AB14: Amount(s) | AC14: Amount(s) | AD14: Amount(s) | AE14: Amount(s) | AF14: Amount(s) | AG14: Amount(s) | AH14: Amount(s) | AI14: Amount(s) | AJ14: Amount(s) | AK14: Amount(s) | AN14: Drawn
A15: =IFERROR(VLOOKUP(C15,'Product List'!$A$2:$C198,2,FALSE),"") | B15: =IFERROR(VLOOKUP(C15,'Product List'!$A$2:$C198,3,FALSE),"") | H15: (Non Reimbursable) | I15: Budget | L15: Revised | M15: Revised
A16: =IFERROR(VLOOKUP(C16,'Product List'!$A$2:$C198,2,FALSE),"") | B16: =IFERROR(VLOOKUP(C16,'Product List'!$A$2:$C198,3,FALSE),"") | E16: 1 | F16: Survey | G16: 7000 | H16: 0 | I16: =+G16-H16 -> 7000 | J16: 0 | K16: =+I16+J16 -> 7000 | L16: =+K16/$K$190 -> 0.00050359712 | M16: =+K16/$T$9 -> 0.085130188 | N16: =+K16-SUM(O16:AL16) -> 7000 | O16: 0 | P16: 0 | Q16: 0 | R16: 0 | S16: 0 | T16: 0 | U16: 0 | V16: 0 | W16: 0 | X16: 0 | Y16: 0 | Z16: 0 | AA16: 0 | AB16: 0 | AC16: 0 | AD16: 0 | AE16: 0 | AF16: 0 | AG16: 0 | AH16: 0 | AI16: 0 | AJ16: 0 | AK16: 0 | AM16: =SUM(O16:AL16) -> 0 | AN16: =IF(K16=0,"",(K16-N16-AL16)/K16) -> 0
A17: =IFERROR(VLOOKUP(C17,'Product List'!$A$2:$C198,2,FALSE),"") | B17: =IFERROR(VLOOKUP(C17,'Product List'!$A$2:$C198,3,FALSE),"") | E17: =+E16+1 -> 2 | F17: Excavation of building and site, backfill, sewer & water connections, elec service, asphalt | G17: 1197367.3 | H17: 300000 | I17: =+G17-H17 -> 897367.29 | J17: 0 | K17: =+I17+J17 -> 897367.29 | L17: =+K17/$K$190 -> 0.064558798 | M17: =+K17/$T$9 -> 10.913292 | N17: =+K17-SUM(O17:AL17) -> 611850.35 | O17: =115016.94-5283.3 -> 109733.64 | P17: 0 | Q17: 161975 | R17: 0 | S17: 0 | T17: 0 | U17: 0 | V17: 0 | W17: 0 | X17: 0 | Y17: 0 | Z17: 0 | AA17: 0 | AB17: 0 | AC17: 0 | AD17: 0 | AE17: 0 | AF17: 0 | AG17: 0 | AH17: 0 | AI17: 0 | AJ17: 0 | AK17: 0 | AL17: 13808.3 | AM17: =SUM(O17:AL17) -> 285516.94 | AN17: =IF(K17=0,"",(K17-N17-AL17)/K17) -> 0.3027842
A18: =IFERROR(VLOOKUP(C18,'Product List'!$A$2:$C198,2,FALSE),"") | B18: =IFERROR(VLOOKUP(C18,'Product List'!$A$2:$C198,3,FALSE),"") | E18: =+E17+1 -> 3 | F18: Footings & Foundations M&L & site M&L | G18: 408552 | H18: 216541.42 | I18: =+G18-H18 -> 192010.58 | J18: 0 | K18: =+I18+J18 -> 192010.58 | L18: =+K18/$K$190 -> 0.013813711 | M18: =+K18/$T$9 -> 2.3351281 | N18: =+K18-SUM(O18:AL18) -> 177823.67 | O18: 7268.96 | P18: 0 | Q18: 2457.93 | R18: 0 | S18: 0 | T18: 0 | U18: 0 | V18: 0 | W18: 0 | X18: 0 | Y18: 0 | Z18: 0 | AA18: 0 | AB18: 0 | AC18: 0 | AD18: 0 | AE18: 0 | AF18: 0 | AG18: 0 | AH18: 0 | AI18: 0 | AJ18: 0 | AK18: 0 | AL18: 4460.02 | AM18: =SUM(O18:AL18) -> 14186.91 | AN18: =IF(K18=0,"",(K18-N18-AL18)/K18) -> 0.050658094
A19: =IFERROR(VLOOKUP(C19,'Product List'!$A$2:$C198,2,FALSE),"") | B19: =IFERROR(VLOOKUP(C19,'Product List'!$A$2:$C198,3,FALSE),"") | E19: =+E18+1 -> 4 | F19: ALL FENCING | G19: 44475 | H19: 0 | I19: =+G19-H19 -> 44475 | J19: 0 | K19: =+I19+J19 -> 44475 | L19: =+K19/$K$190 -> 0.0031996403 | M19: =+K19/$T$9 -> 0.54088073 | N19: =+K19-SUM(O19:AL19) -> 44475 | O19: 0 | P19: 0 | Q19: 0 | R19: 0 | S19: 0 | T19: 0 | U19: 0 | V19: 0 | W19: 0 | X19: 0 | Y19: 0 | Z19: 0 | AA19: 0 | AB19: 0 | AC19: 0 | AD19: 0 | AE19: 0 | AF19: 0 | AG19: 0 | AH19: 0 | AI19: 0 | AJ19: 0 | AK19: 0 | AM19: =SUM(O19:AL19) -> 0 | AN19: =IF(K19=0,"",(K19-N19-AL19)/K19) -> 0
A20: =IFERROR(VLOOKUP(C20,'Product List'!$A$2:$C198,2,FALSE),"") | B20: =IFERROR(VLOOKUP(C20,'Product List'!$A$2:$C198,3,FALSE),"") | E20: =+E19+1 -> 5 | F20: TURNKEY FRAMING, | G20: 2063122 | H20: 100000 | I20: =+G20-H20 -> 1963122 | J20: 0 | K20: =+I20+J20 -> 1963122 | L20: =+K20/$K$190 -> 0.1412318 | M20: =+K20/$T$9 -> 23.874421 | N20: =+K20-SUM(O20:AL20) -> 389153.62 | O20: =504946-25247.3 -> 479698.7 | P20: =820034-41001.7 -> 779032.3 | Q20: 236538.97 | R20: 0 | S20: 0 | T20: 0 | U20: 0 | V20: 0 | W20: 0 | X20: 0 | Y20: 0 | Z20: 0 | AA20: 0 | AB20: 0 | AC20: 0 | AD20: 0 | AE20: 0 | AF20: 0 | AG20: 0 | AH20: 0 | AI20: 0 | AJ20: 0 | AK20: 0 | AL20: 78698.41 | AM20: =SUM(O20:AL20) -> 1573968.4 | AN20: =IF(K20=0,"",(K20-N20-AL20)/K20) -> 0.7616796
A21: =IFERROR(VLOOKUP(C21,'Product List'!$A$2:$C198,2,FALSE),"") | B21: =IFERROR(VLOOKUP(C21,'Product List'!$A$2:$C198,3,FALSE),"") | E21: =+E20+1 -> 6 | F21: Roofing Labor and Materials | G21: 235254.4 | H21: 0 | I21: =+G21-H21 -> 235254.4 | J21: 0 | K21: =+I21+J21 -> 235254.4 | L21: =+K21/$K$190 -> 0.016924777 | M21: =+K21/$T$9 -> 2.8610359 | N21: =+K21-SUM(O21:AL21) -> 235254.4 | O21: 0 | P21: 0 | Q21: 0 | R21: 0 | S21: 0 | T21: 0 | U21: 0 | V21: 0 | W21: 0 | X21: 0 | Y21: 0 | Z21: 0 | AA21: 0 | AB21: 0 | AC21: 0 | AD21: 0 | AE21: 0 | AF21: 0 | AG21: 0 | AH21: 0 | AI21: 0 | AJ21: 0 | AK21: 0 | AM21: =SUM(O21:AL21) -> 0 | AN21: =IF(K21=0,"",(K21-N21-AL21)/K21) -> 0
A22: =IFERROR(VLOOKUP(C22,'Product List'!$A$2:$C198,2,FALSE),"") | B22: =IFERROR(VLOOKUP(C22,'Product List'!$A$2:$C198,3,FALSE),"") | E22: =+E21+1 -> 7 | F22: DECK COATINGS | G22: 72445 | H22: 0 | I22: =+G22-H22 -> 72445 | J22: 0 | K22: =+I22+J22 -> 72445 | L22: =+K22/$K$190 -> 0.0052118705 | M22: =+K22/$T$9 -> 0.88103664 | N22: =+K22-SUM(O22:AL22) -> 72445 | O22: 0 | P22: 0 | Q22: 0 | R22: 0 | S22: 0 | T22: 0 | U22: 0 | V22: 0 | W22: 0 | X22: 0 | Y22: 0 | Z22: 0 | AA22: 0 | AB22: 0 | AC22: 0 | AD22: 0 | AE22: 0 | AF22: 0 | AG22: 0 | AH22: 0 | AI22: 0 | AJ22: 0 | AK22: 0 | AM22: =SUM(O22:AL22) -> 0 | AN22: =IF(K22=0,"",(K22-N22-AL22)/K22) -> 0
A23: =IFERROR(VLOOKUP(C23,'Product List'!$A$2:$C198,2,FALSE),"") | B23: =IFERROR(VLOOKUP(C23,'Product List'!$A$2:$C198,3,FALSE),"") | E23: =+E22+1 -> 8 | F23: Structural steel (Covered parking) | G23: 35813.74 | H23: 0 | I23: =+G23-H23 -> 35813.74 | J23: 0 | K23: =+I23+J23 -> 35813.74 | L23: =+K23/$K$190 -> 0.0025765281 | M23: =+K23/$T$9 -> 0.4355472 | N23: =+K23-SUM(O23:AL23) -> 35813.74 | O23: 0 | P23: 0 | Q23: 0 | R23: 0 | S23: 0 | T23: 0 | U23: 0 | V23: 0 | W23: 0 | X23: 0 | Y23: 0 | Z23: 0 | AA23: 0 | AB23: 0 | AC23: 0 | AD23: 0 | AE23: 0 | AF23: 0 | AG23: 0 | AH23: 0 | AI23: 0 | AJ23: 0 | AK23: 0 | AM23: =SUM(O23:AL23) -> 0 | AN23: =IF(K23=0,"",(K23-N23-AL23)/K23) -> 0
A24: =IFERROR(VLOOKUP(C24,'Product List'!$A$2:$C198,2,FALSE),"") | B24: =IFERROR(VLOOKUP(C24,'Product List'!$A$2:$C198,3,FALSE),"") | E24: =+E23+1 -> 9 | F24: ALL OTHER STEEL FEATURES | G24: 196050 | H24: 0 | I24: =+G24-H24 -> 196050 | J24: 0 | K24: =+I24+J24 -> 196050 | L24: =+K24/$K$190 -> 0.014104317 | M24: =+K24/$T$9 -> 2.3842533 | N24: =+K24-SUM(O24:AL24) -> 196050 | O24: 0 | P24: 0 | Q24: 0 | R24: 0 | S24: 0 | T24: 0 | U24: 0 | V24: 0 | W24: 0 | X24: 0 | Y24: 0 | Z24: 0 | AA24: 0 | AB24: 0 | AC24: 0 | AD24: 0 | AE24: 0 | AF24: 0 | AG24: 0 | AH24: 0 | AI24: 0 | AJ24: 0 | AK24: 0 | AM24: =SUM(O24:AL24) -> 0 | AN24: =IF(K24=0,"",(K24-N24-AL24)/K24) -> 0
A25: =IFERROR(VLOOKUP(C25,'Product List'!$A$2:$C198,2,FALSE),"") | B25: =IFERROR(VLOOKUP(C25,'Product List'!$A$2:$C198,3,FALSE),"") | E25: =+E24+1 -> 10 | F25: Windows | G25: 170000 | H25: 0 | I25: =+G25-H25 -> 170000 | J25: 0 | K25: =+I25+J25 -> 170000 | L25: =+K25/$K$190 -> 0.012230216 | M25: =+K25/$T$9 -> 2.0674474 | N25: =+K25-SUM(O25:AL25) -> 170000 | O25: 0 | P25: 0 | Q25: 0 | R25: 0 | S25: 0 | T25: 0 | U25: 0 | V25: 0 | W25: 0 | X25: 0 | Y25: 0 | Z25: 0 | AA25: 0 | AB25: 0 | AC25: 0 | AD25: 0 | AE25: 0 | AF25: 0 | AG25: 0 | AH25: 0 | AI25: 0 | AJ25: 0 | AK25: 0 | AM25: =SUM(O25:AL25) -> 0 | AN25: =IF(K25=0,"",(K25-N25-AL25)/K25) -> 0
A26: =IFERROR(VLOOKUP(C26,'Product List'!$A$2:$C198,2,FALSE),"") | B26: =IFERROR(VLOOKUP(C26,'Product List'!$A$2:$C198,3,FALSE),"") | E26: =+E25+1 -> 11 | F26: Store Front L&M | G26: 95488 | H26: 0 | I26: =+G26-H26 -> 95488 | J26: 0 | K26: =+I26+J26 -> 95488 | L26: =+K26/$K$190 -> 0.0068696403 | M26: =+K26/$T$9 -> 1.1612731 | N26: =+K26-SUM(O26:AL26) -> 95488 | O26: 0 | P26: 0 | Q26: 0 | R26: 0 | S26: 0 | T26: 0 | U26: 0 | V26: 0 | W26: 0 | X26: 0 | Y26: 0 | Z26: 0 | AA26: 0 | AB26: 0 | AC26: 0 | AD26: 0 | AE26: 0 | AF26: 0 | AG26: 0 | AH26: 0 | AI26: 0 | AJ26: 0 | AK26: 0 | AM26: =SUM(O26:AL26) -> 0 | AN26: =IF(K26=0,"",(K26-N26-AL26)/K26) -> 0
A27: =IFERROR(VLOOKUP(C27,'Product List'!$A$2:$C198,2,FALSE),"") | B27: =IFERROR(VLOOKUP(C27,'Product List'!$A$2:$C198,3,FALSE),"") | E27: =+E26+1 -> 12 | F27: ELEVATOR | G27: 255500 | H27: 0 | I27: =+G27-H27 -> 255500 | J27: 0 | K27: =+I27+J27 -> 255500 | L27: =+K27/$K$190 -> 0.018381295 | M27: =+K27/$T$9 -> 3.1072519 | N27: =+K27-SUM(O27:AL27) -> 255500 | O27: 0 | P27: 0 | Q27: 0 | R27: 0 | S27: 0 | T27: 0 | U27: 0 | V27: 0 | W27: 0 | X27: 0 | Y27: 0 | Z27: 0 | AA27: 0 | AB27: 0 | AC27: 0 | AD27: 0 | AE27: 0 | AF27: 0 | AG27: 0 | AH27: 0 | AI27: 0 | AJ27: 0 | AK27: 0 | AM27: =SUM(O27:AL27) -> 0 | AN27: =IF(K27=0,"",(K27-N27-AL27)/K27) -> 0
A28: =IFERROR(VLOOKUP(C28,'Product List'!$A$2:$C198,2,FALSE),"") | B28: =IFERROR(VLOOKUP(C28,'Product List'!$A$2:$C198,3,FALSE),"") | E28: =+E27+1 -> 13 | F28: HM door labor | G28: 18575 | H28: 0 | I28: =+G28-H28 -> 18575 | J28: 0 | K28: =+I28+J28 -> 18575 | L28: =+K28/$K$190 -> 0.0013363309 | M28: =+K28/$T$9 -> 0.22589904 | N28: =+K28-SUM(O28:AL28) -> 18575 | O28: 0 | P28: 0 | Q28: 0 | R28: 0 | S28: 0 | T28: 0 | U28: 0 | V28: 0 | W28: 0 | X28: 0 | Y28: 0 | Z28: 0 | AA28: 0 | AB28: 0 | AC28: 0 | AD28: 0 | AE28: 0 | AF28: 0 | AG28: 0 | AH28: 0 | AI28: 0 | AJ28: 0 | AK28: 0 | AM28: =SUM(O28:AL28) -> 0 | AN28: =IF(K28=0,"",(K28-N28-AL28)/K28) -> 0
A29: =IFERROR(VLOOKUP(C29,'Product List'!$A$2:$C198,2,FALSE),"") | B29: =IFERROR(VLOOKUP(C29,'Product List'!$A$2:$C198,3,FALSE),"") | E29: =+E28+1 -> 14 | F29: Plumbing | G29: 1125000 | H29: 338750 | I29: =+G29-H29 -> 786250 | J29: 0 | K29: =+I29+J29 -> 786250 | L29: =+K29/$K$190 -> 0.056564748 | M29: =+K29/$T$9 -> 9.5619444 | N29: =+K29-SUM(O29:AL29) -> 600000 | O29: 0 | P29: =62500-3125 -> 59375 | Q29: 106875 | R29: 0 | S29: 0 | T29: 0 | U29: 0 | V29: 0 | W29: 0 | X29: 0 | Y29: 0 | Z29: 0 | AA29: 0 | AB29: 0 | AC29: 0 | AD29: 0 | AE29: 0 | AF29: 0 | AG29: 0 | AH29: 0 | AI29: 0 | AJ29: 0 | AK29: 0 | AL29: 20000 | AM29: =SUM(O29:AL29) -> 186250 | AN29: =IF(K29=0,"",(K29-N29-AL29)/K29) -> 0.21144674
A30: =IFERROR(VLOOKUP(C30,'Product List'!$A$2:$C198,2,FALSE),"") | B30: =IFERROR(VLOOKUP(C30,'Product List'!$A$2:$C198,3,FALSE),"") | E30: =+E29+1 -> 15 | F30: HVAC | G30: 1395000 | H30: 150000 | I30: =+G30-H30 -> 1245000 | J30: 0 | K30: =+I30+J30 -> 1245000 | L30: =+K30/$K$190 -> 0.089568345 | M30: =+K30/$T$9 -> 15.141012 | N30: =+K30-SUM(O30:AL30) -> 1125000 | O30: 0 | P30: 0 | Q30: 114000 | R30: 0 | S30: 0 | T30: 0 | U30: 0 | V30: 0 | W30: 0 | X30: 0 | Y30: 0 | Z30: 0 | AA30: 0 | AB30: 0 | AC30: 0 | AD30: 0 | AE30: 0 | AF30: 0 | AG30: 0 | AH30: 0 | AI30: 0 | AJ30: 0 | AK30: 0 | AL30: 6000 | AM30: =SUM(O30:AL30) -> 120000 | AN30: =IF(K30=0,"",(K30-N30-AL30)/K30) -> 0.091566265
A31: =IFERROR(VLOOKUP(C31,'Product List'!$A$2:$C198,2,FALSE),"") | B31: =IFERROR(VLOOKUP(C31,'Product List'!$A$2:$C198,3,FALSE),"") | E31: =+E30+1 -> 16 | F31: Electric | G31: 1186352 | H31: 400000 | I31: =+G31-H31 -> 786352 | J31: 0 | K31: =+I31+J31 -> 786352 | L31: =+K31/$K$190 -> 0.056572086 | M31: =+K31/$T$9 -> 9.5631848 | N31: =+K31-SUM(O31:AL31) -> 786352 | O31: 0 | P31: 0 | Q31: 0 | R31: 0 | S31: 0 | T31: 0 | U31: 0 | V31: 0 | W31: 0 | X31: 0 | Y31: 0 | Z31: 0 | AA31: 0 | AB31: 0 | AC31: 0 | AD31: 0 | AE31: 0 | AF31: 0 | AG31: 0 | AH31: 0 | AI31: 0 | AJ31: 0 | AK31: 0 | AM31: =SUM(O31:AL31) -> 0 | AN31: =IF(K31=0,"",(K31-N31-AL31)/K31) -> 0
A32: =IFERROR(VLOOKUP(C32,'Product List'!$A$2:$C198,2,FALSE),"") | B32: =IFERROR(VLOOKUP(C32,'Product List'!$A$2:$C198,3,FALSE),"") | E32: =+E31+1 -> 17 | F32: SPRINKLER SYSTEM | G32: 156271 | H32: 0 | I32: =+G32-H32 -> 156271 | J32: 0 | K32: =+I32+J32 -> 156271 | L32: =+K32/$K$190 -> 0.011242518 | M32: =+K32/$T$9 -> 1.9004828 | N32: =+K32-SUM(O32:AL32) -> 156271 | O32: 0 | P32: 0 | Q32: 0 | R32: 0 | S32: 0 | T32: 0 | U32: 0 | V32: 0 | W32: 0 | X32: 0 | Y32: 0 | Z32: 0 | AA32: 0 | AB32: 0 | AC32: 0 | AD32: 0 | AE32: 0 | AF32: 0 | AG32: 0 | AH32: 0 | AI32: 0 | AJ32: 0 | AK32: 0 | AM32: =SUM(O32:AL32) -> 0 | AN32: =IF(K32=0,"",(K32-N32-AL32)/K32) -> 0
A33: =IFERROR(VLOOKUP(C33,'Product List'!$A$2:$C198,2,FALSE),"") | B33: =IFERROR(VLOOKUP(C33,'Product List'!$A$2:$C198,3,FALSE),"") | E33: =+E32+1 -> 18 | F33: FIRE CAULKING | G33: 10000 | H33: 0 | I33: =+G33-H33 -> 10000 | J33: 0 | K33: =+I33+J33 -> 10000 | L33: =+K33/$K$190 -> 0.00071942446 | M33: =+K33/$T$9 -> 0.12161455 | N33: =+K33-SUM(O33:AL33) -> 10000 | O33: 0 | P33: 0 | Q33: 0 | R33: 0 | S33: 0 | T33: 0 | U33: 0 | V33: 0 | W33: 0 | X33: 0 | Y33: 0 | Z33: 0 | AA33: 0 | AB33: 0 | AC33: 0 | AD33: 0 | AE33: 0 | AF33: 0 | AG33: 0 | AH33: 0 | AI33: 0 | AJ33: 0 | AK33: 0 | AM33: =SUM(O33:AL33) -> 0 | AN33: =IF(K33=0,"",(K33-N33-AL33)/K33) -> 0
A34: =IFERROR(VLOOKUP(C34,'Product List'!$A$2:$C198,2,FALSE),"") | B34: =IFERROR(VLOOKUP(C34,'Product List'!$A$2:$C198,3,FALSE),"") | E34: =+E33+1 -> 19 | F34: GYPCRETE | G34: 77757.03 | H34: 0 | I34: =+G34-H34 -> 77757.03 | J34: 0 | K34: =+I34+J34 -> 77757.03 | L34: =+K34/$K$190 -> 0.0055940309 | M34: =+K34/$T$9 -> 0.94563866 | N34: =+K34-SUM(O34:AL34) -> 77757.03 | O34: 0 | P34: 0 | Q34: 0 | R34: 0 | S34: 0 | T34: 0 | U34: 0 | V34: 0 | W34: 0 | X34: 0 | Y34: 0 | Z34: 0 | AA34: 0 | AB34: 0 | AC34: 0 | AD34: 0 | AE34: 0 | AF34: 0 | AG34: 0 | AH34: 0 | AI34: 0 | AJ34: 0 | AK34: 0 | AM34: =SUM(O34:AL34) -> 0 | AN34: =IF(K34=0,"",(K34-N34-AL34)/K34) -> 0
A35: =IFERROR(VLOOKUP(C35,'Product List'!$A$2:$C198,2,FALSE),"") | B35: =IFERROR(VLOOKUP(C35,'Product List'!$A$2:$C198,3,FALSE),"") | E35: =+E34+1 -> 20 | F35: Insulation | G35: 232552 | H35: 2600.62 | I35: =+G35-H35 -> 229951.38 | J35: 0 | K35: =+I35+J35 -> 229951.38 | L35: =+K35/$K$190 -> 0.016543265 | M35: =+K35/$T$9 -> 2.7965435 | N35: =+K35-SUM(O35:AL35) -> 229814.5 | O35: 0 | P35: 0 | Q35: 0 | R35: 0 | S35: 0 | T35: 0 | U35: 0 | V35: 0 | W35: 0 | X35: 0 | Y35: 0 | Z35: 0 | AA35: 0 | AB35: 0 | AC35: 0 | AD35: 0 | AE35: 0 | AF35: 0 | AG35: 0 | AH35: 0 | AI35: 0 | AJ35: 0 | AK35: 0 | AL35: 136.88 | AM35: =SUM(O35:AL35) -> 136.88 | AN35: =IF(K35=0,"",(K35-N35-AL35)/K35) -> 0
A36: =IFERROR(VLOOKUP(C36,'Product List'!$A$2:$C198,2,FALSE),"") | B36: =IFERROR(VLOOKUP(C36,'Product List'!$A$2:$C198,3,FALSE),"") | E36: =+E35+1 -> 21 | F36: Sheetrock | G36: 850750 | H36: 0 | I36: =+G36-H36 -> 850750 | J36: 0 | K36: =+I36+J36 -> 850750 | L36: =+K36/$K$190 -> 0.061205036 | M36: =+K36/$T$9 -> 10.346358 | N36: =+K36-SUM(O36:AL36) -> 850750 | O36: 0 | P36: 0 | Q36: 0 | R36: 0 | S36: 0 | T36: 0 | U36: 0 | V36: 0 | W36: 0 | X36: 0 | Y36: 0 | Z36: 0 | AA36: 0 | AB36: 0 | AC36: 0 | AD36: 0 | AE36: 0 | AF36: 0 | AG36: 0 | AH36: 0 | AI36: 0 | AJ36: 0 | AK36: 0 | AM36: =SUM(O36:AL36) -> 0 | AN36: =IF(K36=0,"",(K36-N36-AL36)/K36) -> 0
A37: =IFERROR(VLOOKUP(C37,'Product List'!$A$2:$C198,2,FALSE),"") | B37: =IFERROR(VLOOKUP(C37,'Product List'!$A$2:$C198,3,FALSE),"") | E37: =+E36+1 -> 22 | F37: 2 layers of dens glass | G37: 120000 | H37: 0 | I37: =+G37-H37 -> 120000 | J37: 0 | K37: =+I37+J37 -> 120000 | L37: =+K37/$K$190 -> 0.0086330935 | M37: =+K37/$T$9 -> 1.4593747 | N37: =+K37-SUM(O37:AL37) -> 120000 | O37: 0 | P37: 0 | Q37: 0 | R37: 0 | S37: 0 | T37: 0 | U37: 0 | V37: 0 | W37: 0 | X37: 0 | Y37: 0 | Z37: 0 | AA37: 0 | AB37: 0 | AC37: 0 | AD37: 0 | AE37: 0 | AF37: 0 | AG37: 0 | AH37: 0 | AI37: 0 | AJ37: 0 | AK37: 0 | AM37: =SUM(O37:AL37) -> 0 | AN37: =IF(K37=0,"",(K37-N37-AL37)/K37) -> 0
A38: =IFERROR(VLOOKUP(C38,'Product List'!$A$2:$C198,2,FALSE),"") | B38: =IFERROR(VLOOKUP(C38,'Product List'!$A$2:$C198,3,FALSE),"") | E38: =+E37+1 -> 23 | F38: FINISH MATERIALS MISC | G38: 325000 | H38: 0 | I38: =+G38-H38 -> 325000 | J38: 0 | K38: =+I38+J38 -> 325000 | L38: =+K38/$K$190 -> 0.023381295 | M38: =+K38/$T$9 -> 3.952473 | N38: =+K38-SUM(O38:AL38) -> 325000 | O38: 0 | P38: 0 | Q38: 0 | R38: 0 | S38: 0 | T38: 0 | U38: 0 | V38: 0 | W38: 0 | X38: 0 | Y38: 0 | Z38: 0 | AA38: 0 | AB38: 0 | AC38: 0 | AD38: 0 | AE38: 0 | AF38: 0 | AG38: 0 | AH38: 0 | AI38: 0 | AJ38: 0 | AK38: 0 | AM38: =SUM(O38:AL38) -> 0 | AN38: =IF(K38=0,"",(K38-N38-AL38)/K38) -> 0
A39: =IFERROR(VLOOKUP(C39,'Product List'!$A$2:$C198,2,FALSE),"") | B39: =IFERROR(VLOOKUP(C39,'Product List'!$A$2:$C198,3,FALSE),"") | E39: =+E38+1 -> 24 | F39: Finish Labor | G39: 95000 | H39: 0 | I39: =+G39-H39 -> 95000 | J39: 0 | K39: =+I39+J39 -> 95000 | L39: =+K39/$K$190 -> 0.0068345324 | M39: =+K39/$T$9 -> 1.1553383 | N39: =+K39-SUM(O39:AL39) -> 95000 | O39: 0 | P39: 0 | Q39: 0 | R39: 0 | S39: 0 | T39: 0 | U39: 0 | V39: 0 | W39: 0 | X39: 0 | Y39: 0 | Z39: 0 | AA39: 0 | AB39: 0 | AC39: 0 | AD39: 0 | AE39: 0 | AF39: 0 | AG39: 0 | AH39: 0 | AI39: 0 | AJ39: 0 | AK39: 0 | AM39: =SUM(O39:AL39) -> 0 | AN39: =IF(K39=0,"",(K39-N39-AL39)/K39) -> 0
A40: =IFERROR(VLOOKUP(C40,'Product List'!$A$2:$C198,2,FALSE),"") | B40: =IFERROR(VLOOKUP(C40,'Product List'!$A$2:$C198,3,FALSE),"") | E40: =+E39+1 -> 25 | F40: Interior Paint | G40: 213852.35 | H40: 213852.35 | I40: =+G40-H40 -> 0 | J40: 0 | K40: =+I40+J40 -> 0 | L40: =+K40/$K$190 -> 0 | M40: =+K40/$T$9 -> 0 | N40: =+K40-SUM(O40:AL40) -> 0 | O40: 0 | P40: 0 | Q40: 0 | R40: 0 | S40: 0 | T40: 0 | U40: 0 | V40: 0 | W40: 0 | X40: 0 | Y40: 0 | Z40: 0 | AA40: 0 | AB40: 0 | AC40: 0 | AD40: 0 | AE40: 0 | AF40: 0 | AG40: 0 | AH40: 0 | AI40: 0 | AJ40: 0 | AK40: 0 | AM40: =SUM(O40:AL40) -> 0 | AN40: =IF(K40=0,"",(K40-N40-AL40)/K40)
...
