Workbook

Sheet Cost To Complete
C2: Hunter's Landing Continuation Sheet
I5: Rich Development
F6: Scheduled Value
B7: Item # | C7: # | D7: DESCRIPTION OF WORK | F7: Rich Development | G7: Change Orders/Reallocation | H7: Total | I7: Amount Paid to Date | J7: Retention held to Date | K7: Contract cost to complete including retention | L7: Change Order cost to complete including retention | M7: TOTAL COST TO COMPLETE | N7: DIFFERENCE BETWEEN SCHEDULED VALUE AND COST TO COMPLETE
P8: NOTES
B10: 001 | C10: EXCAVATION/SITE | D10: Survey | F10: 5500 | G10: 515 | H10: =F10+G10 -> 6015 | I10: 6015 | J10: 0 | K10: 750 | M10: =J10+K10+L10 -> 750 | N10: =H10-I10-M10 -> -750 | P10: Fencing & Pond surveys
B11: 002 | C11: EXCAVATION/SITE | D11: Excavation | F11: 364814.62 | H11: =F11+G11 -> 364814.62 | I11: =SUM('Continuation Sheet'!I11:O11) -> 284961.84 | J11: 26859.91 | K11: =29346+57493 -> 86839 | L11: =10535+5000 -> 15535 | M11: =J11+K11+L11 -> 129233.91 | N11: =H11-I11-M11 -> -49381.13
B12: 003 | C12: EXCAVATION/SITE | D12: Concrete | F12: 208293.28 | H12: =F12+G12 -> 208293.28 | I12: =SUM('Continuation Sheet'!I12:O12) -> 127580.19 | J12: =3614.11 -> 3614.11 | K12: =38640.58+31928.33+15000 -> 85568.91 | M12: =J12+K12+L12 -> 89183.02 | N12: =H12-I12-M12 -> -8469.93
B13: 004 | C13: EXCAVATION/SITE | D13: 12th UDOT | F13: 17550 | H13: =F13+G13 -> 17550 | I13: =SUM('Continuation Sheet'!I13:O13) -> 0 | K13: 49414 | L13: =66495+3000 -> 69495 | M13: =J13+K13+L13 -> 118909 | N13: =H13-I13-M13 -> -101359
B14: 005 | C14: EXCAVATION/SITE | D14: All Fencing | F14: 44475 | H14: =F14+G14 -> 44475 | I14: =SUM('Continuation Sheet'!I14:O14) -> 0 | K14: 44475 | L14: =3845+3714.31 -> 7559.31 | M14: =J14+K14+L14 -> 52034.31 | N14: =H14-I14-M14 -> -7559.31
B15: 006 | C15: EXCAVATION/SITE | D15: Track out Pad entire building | F15: 49700 | H15: =F15+G15 -> 49700 | I15: =SUM('Continuation Sheet'!I15:O15) -> 49700 | M15: =J15+K15+L15 -> 0 | N15: =H15-I15-M15 -> 0
B16: 007 | C16: FRAME/ROOF | D16: Turnkey Frame/Garage | F16: 43755 | G16: -20000 | H16: =F16+G16 -> 23755 | I16: =SUM('Continuation Sheet'!I16:O16) -> 16365.04 | J16: 851.75 | M16: =J16+K16+L16 -> 851.75 | N16: =H16-I16-M16 -> 6538.21
B17: 008 | C17: FRAME/ROOF | D17: Garage Roof | F17: 12500 | H17: =F17+G17 -> 12500 | I17: =SUM('Continuation Sheet'!I17:O17) -> 0 | K17: 12500 | M17: =J17+K17+L17 -> 12500 | N17: =H17-I17-M17 -> 0
B18: 009 | C18: FRAME/ROOF | D18: Roofing L&M | F18: 63244 | H18: =F18+G18 -> 63244 | I18: =SUM('Continuation Sheet'!I18:O18) -> 50372.23 | J18: =4242.8 -> 4242.8 | K18: =27500+3244.18 -> 30744.18 | M18: =J18+K18+L18 -> 34986.98 | N18: =H18-I18-M18 -> -22115.21
B19: 010 | C19: FRAME/ROOF | D19: Deck Coatings | F19: 97940 | H19: =F19+G19 -> 97940 | I19: =SUM('Continuation Sheet'!I19:O19) -> 80613.2 | J19: =1066.92+4242.8 -> 5309.72 | K19: =5761 -> 5761 | L19: 10598.4 | M19: =J19+K19+L19 -> 21669.12 | N19: =H19-I19-M19 -> -4342.32 | P19: Decks lvl 2-5 done, Urbane needs to bill the rest of their contract amount, My Roof has a bill for the rest of the amentities deck change order
B20: 011 | C20: FRAME/ROOF | D20: Structural Steel-Parking | F20: 84577 | G20: -24000 | H20: =F20+G20 -> 60577 | I20: =SUM('Continuation Sheet'!I20:O20) -> 0 | J20: 17699.18 | M20: =J20+K20+L20 -> 17699.18 | N20: =H20-I20-M20 -> 42877.82
B21: 012 | C21: FRAME/ROOF | D21: All other Steel Features | F21: 623901.14 | G21: -221107.65 | H21: =F21+G21 -> 402793.49 | I21: =SUM('Continuation Sheet'!I21:O21) -> 250237.61 | M21: =J21+K21+L21 -> 0 | N21: =H21-I21-M21 -> 152555.88
B22: 013 | C22: FRAME/ROOF | D22: Garage Door For Trash | F22: 4500 | H22: =F22+G22 -> 4500 | I22: =SUM('Continuation Sheet'!I22:O22) -> 0 | M22: =J22+K22+L22 -> 0 | N22: =H22-I22-M22 -> 4500
B23: 014 | C23: FRAME/ROOF | D23: Store Front Labor | F23: 7500 | G23: 5053.48 | H23: =F23+G23 -> 12553.48 | I23: =SUM('Continuation Sheet'!I23:O23) -> 12553.48 | M23: =J23+K23+L23 -> 0 | N23: =H23-I23-M23 -> 0
B24: 015 | C24: FRAME/ROOF | D24: Elevator | F24: 70150 | H24: =F24+G24 -> 70150 | I24: =SUM('Continuation Sheet'!I24:O24) -> 0 | M24: =J24+K24+L24 -> 0 | N24: =H24-I24-M24 -> 70150
B25: 016 | C25: FRAME/ROOF | D25: HM Door Labor | F25: 52475 | G25: -19908.96 | H25: =F25+G25 -> 32566.04 | I25: =SUM('Continuation Sheet'!I25:O25) -> 32480.8 | M25: =J25+K25+L25 -> 0 | N25: =H25-I25-M25 -> 85.24
B26: 017 | C26: MEP TRADES | D26: Plumbing | F26: 524500 | H26: =F26+G26 -> 524500 | I26: =SUM('Continuation Sheet'!I26:O26) -> 381460.72 | J26: =2200 -> 2200 | K26: =3600+3600+60080 -> 67280 | M26: =J26+K26+L26 -> 69480 | N26: =H26-I26-M26 -> 73559.28
B27: 018 | C27: MEP TRADES | D27: HVAC | F27: 1244900 | H27: =F27+G27 -> 1244900 | I27: =SUM('Continuation Sheet'!I27:O27) -> 934132.15 | M27: =J27+K27+L27 -> 0 | N27: =H27-I27-M27 -> 310767.85
B28: 019 | C28: MEP TRADES | D28: Electric | F28: 434737.1 | H28: =F28+G28 -> 434737.1 | I28: =SUM('Continuation Sheet'!I28:O28) -> 129850.11 | M28: =J28+K28+L28 -> 0 | N28: =H28-I28-M28 -> 304886.99
B29: 020 | C29: MEP TRADES | D29: 3 Electric Car Station | F29: 37500 | H29: =F29+G29 -> 37500 | I29: =SUM('Continuation Sheet'!I29:O29) -> 0 | M29: =J29+K29+L29 -> 0 | N29: =H29-I29-M29 -> 37500
B30: 021 | C30: MEP TRADES | D30: Sprinkler System | F30: 168681 | H30: =F30+G30 -> 168681 | I30: =SUM('Continuation Sheet'!I30:O30) -> 91342.53 | M30: =J30+K30+L30 -> 0 | N30: =H30-I30-M30 -> 77338.47
B31: 022 | C31: MEP TRADES | D31: Fire Caulk | F31: 14750 | H31: =F31+G31 -> 14750 | I31: =SUM('Continuation Sheet'!I31:O31) -> 3515.03 | M31: =J31+K31+L31 -> 0 | N31: =H31-I31-M31 -> 11234.97
B32: 023 | C32: FINISHES | D32: Gypcrete | F32: 152486 | H32: =F32+G32 -> 152486 | I32: =SUM('Continuation Sheet'!I32:O32) -> 141181.97 | M32: =J32+K32+L32 -> 0 | N32: =H32-I32-M32 -> 11304.03
B33: 024 | C33: FINISHES | D33: Insulation | F33: 222919 | G33: -25000 | H33: =F33+G33 -> 197919 | I33: =SUM('Continuation Sheet'!I33:O33) -> 184045.4 | J33: 9686.6 | M33: =J33+K33+L33 -> 9686.6 | N33: =H33-I33-M33 -> 4187
B34: 025 | C34: FINISHES | D34: Sheetrock | F34: 1467345 | H34: =F34+G34 -> 1467345 | I34: =SUM('Continuation Sheet'!I34:O34) -> 1126879.1 | J34: =51371.44+3875 -> 55246.44 | K34: =357781.56 -> 357781.56 | M34: =J34+K34+L34 -> 413028 | N34: =H34-I34-M34 -> -72562.14 | P34: Cabinets/Countertops were taken out of this category because there was no category funded for them
B35: 026 | C35: FINISHES | D35: Finish Materials Misc | F35: 25000 | G35: 146985.68 | H35: =F35+G35 -> 171985.68 | I35: =SUM('Continuation Sheet'!I35:O35) -> 170079.85 | M35: =J35+K35+L35 -> 0 | N35: =H35-I35-M35 -> 1905.83
B36: 027 | C36: FINISHES | D36: Finish Labor | F36: 189135 | G36: -50313.72 | H36: =F36+G36 -> 138821.28 | I36: =SUM('Continuation Sheet'!I36:O36) -> 135233.66 | M36: =J36+K36+L36 -> 0 | N36: =H36-I36-M36 -> 3587.62
B37: 028 | C37: FINISHES | D37: Interior Paint | F37: 303668.8 | H37: =F37+G37 -> 303668.8 | I37: =SUM('Continuation Sheet'!I37:O37) -> 136304.72 | M37: =J37+K37+L37 -> 0 | N37: =H37-I37-M37 -> 167364.08
B38: 029 | C38: FINISHES | D38: Equipment Cabinets | F38: 6000 | H38: =F38+G38 -> 6000 | I38: =SUM('Continuation Sheet'!I38:O38) -> 0 | M38: =J38+K38+L38 -> 0 | N38: =H38-I38-M38 -> 6000
B39: 030 | C39: FINISHES | D39: Garage Doors | F39: 14081.4 | H39: =F39+G39 -> 14081.4 | I39: =SUM('Continuation Sheet'!I39:O39) -> 0 | M39: =J39+K39+L39 -> 0 | N39: =H39-I39-M39 -> 14081.4
B40: 031 | C40: FINISHES | D40: Floor Prep | F40: 10000 | H40: =F40+G40 -> 10000 | I40: =SUM('Continuation Sheet'!I40:O40) -> 0 | M40: =J40+K40+L40 -> 0 | N40: =H40-I40-M40 -> 10000
B41: 032 | C41: FINISHES | D41: Hardware & Install Labor | F41: 65000 | H41: =F41+G41 -> 65000 | I41: =SUM('Continuation Sheet'!I41:O41) -> 15682.52 | M41: =J41+K41+L41 -> 0 | N41: =H41-I41-M41 -> 49317.48
B42: 033 | C42: FINISHES | D42: Fire Extinguishers | F42: 7850 | H42: =F42+G42 -> 7850 | I42: =SUM('Continuation Sheet'!I42:O42) -> 0 | M42: =J42+K42+L42 -> 0 | N42: =H42-I42-M42 -> 7850
B43: 034 | C43: FINISHES | D43: Mirrors | F43: 24750 | G43: -15000 | H43: =F43+G43 -> 9750 | I43: =SUM('Continuation Sheet'!I43:O43) -> 0 | M43: =J43+K43+L43 -> 0 | N43: =H43-I43-M43 -> 9750
B44: 035 | C44: FINISHES | D44: Flooring,Wall Tile M&L | F44: 340975 | H44: =F44+G44 -> 340975 | I44: =SUM('Continuation Sheet'!I44:O44) -> 172071.22 | M44: =J44+K44+L44 -> 0 | N44: =H44-I44-M44 -> 168903.78
...

Sheet Continuation Sheet
C2: Hunter's Landing Continuation Sheet
I5: Rich Development
F6: Scheduled Value | I6: 45533 | J6: 45546 | T6: Retainage | V6: COST TO COMPLETE
B7: Item # | C7: # | D7: DESCRIPTION OF WORK | F7: Rich Development | G7: Change Orders/Reallocation | H7: Total | I7: Draw 20 | J7: Draw 21 | K7: Draw 22 | L7: Draw 23 | M7: Draw 24 | N7: Draw 25 | O7: Draw 26 | P7: Draw 27 | Q7: TOTAL COMPLETED AND STORED TO DATE | R7: Percent Complete | S7: BALANCE TO FINISH | T7: Value 5% | V7: Contract Amount | W7: Retention | X7: CO Amount for cost to complete | Y7: Project CO | Z7: CO #
B10: 001 | C10: EXCAVATION/SITE | D10: Survey | F10: 5500 | G10: 515 | H10: =F10+G10 -> 6015 | K10: 1340 | M10: 4675 | Q10: =SUM(I10:P10) -> 6015 | R10: =Q10/H10 -> 1 | S10: =H10-Q10 -> 0 | V10: 750 | X10: 0
B11: 002 | C11: EXCAVATION/SITE | D11: Excavation | F11: 364814.62 | H11: =F11+G11 -> 364814.62 | J11: 11270 | M11: 273691.84 | P11: =59368.35+37886.95 -> 97255.3 | Q11: =SUM(I11:P11) -> 382217.14 | R11: =Q11/H11 -> 1.0477024 | S11: =H11-Q11 -> -17402.52 | V11: 97255.3 | W11: 38228.61
B12: 003 | C12: EXCAVATION/SITE | D12: Concrete | F12: 208293.28 | H12: =F12+G12 -> 208293.28 | K12: =192.62+710.13+795+20433.48+29710.3 -> 51841.53 | L12: =8299.2+8187.9 -> 16487.1 | M12: =14946.08+483.38+913.5+1539.25+2352.28+2921.58+1325.59+2176.28+1354.54+2128.01+687.56+2351.28+2176.28 -> 35355.61 | O12: =7008.42+1175+15712.53 -> 23895.95 | P12: =15064.46+18288.05+16863.87 -> 50216.38 | Q12: =SUM(I12:P12) -> 177796.57 | R12: =Q12/H12 -> 0.85358764 | S12: =H12-Q12 -> 30496.71 | V12: =P12+S12 -> 80713.09 | W12: =3988.61 -> 3988.61
B13: 004 | C13: EXCAVATION/SITE | D13: 12th UDOT | F13: 17550 | H13: =F13+G13 -> 17550 | Q13: =SUM(I13:P13) -> 0 | R13: =Q13/H13 -> 0 | S13: =H13-Q13 -> 17550 | V13: =S13 -> 17550 | X13: =66495+25000 -> 91495
B14: 005 | C14: EXCAVATION/SITE | D14: All Fencing | F14: 44475 | H14: =F14+G14 -> 44475 | P14: 10035.61 | Q14: =SUM(I14:P14) -> 10035.61 | R14: =Q14/H14 -> 0.22564609 | S14: =H14-Q14 -> 34439.39 | V14: =S14 -> 34439.39 | W14: 119 | X14: =2616+1230+3714.31 -> 7560.31
B15: 006 | C15: EXCAVATION/SITE | D15: Track out Pad entire building | F15: 49700 | H15: =F15+G15 -> 49700 | I15: 37020 | J15: 12680 | Q15: =SUM(I15:P15) -> 49700 | R15: =Q15/H15 -> 1 | S15: =H15-Q15 -> 0 | V15: 0 | Y15: 61154.15
B16: 007 | C16: FRAME/ROOF | D16: Turnkey Frame/Garage | F16: 43755 | G16: -20000 | H16: =F16+G16 -> 23755 | K16: =181.79+16183.25 -> 16365.04 | Q16: =SUM(I16:P16) -> 16365.04 | R16: =Q16/H16 -> 0.68890928 | S16: =H16-Q16 -> 7389.96 | V16: 0 | W16: =851.75 -> 851.75
B17: 008 | C17: FRAME/ROOF | D17: Garage Roof | F17: 12500 | H17: =F17+G17 -> 12500 | Q17: =SUM(I17:P17) -> 0 | R17: =Q17/H17 -> 0 | S17: =H17-Q17 -> 12500
B18: 009 | C18: FRAME/ROOF | D18: Roofing L&M | F18: 63244 | H18: =F18+G18 -> 63244 | L18: 30100.75 | O18: 20271.48 | P18: 41081.98 | Q18: =SUM(I18:P18) -> 91454.21 | R18: =Q18/H18 -> 1.4460535 | S18: =H18-Q18 -> -28210.21
B19: 010 | C19: FRAME/ROOF | D19: Deck Coatings | F19: 97940 | H19: =F19+G19 -> 97940 | M19: 80613.2 | P19: 10068.48 | Q19: =SUM(I19:P19) -> 90681.68 | R19: =Q19/H19 -> 0.92589014 | S19: =H19-Q19 -> 7258.32 | X19: 32000 | AA19: Amenities Deck
B20: 011 | C20: FRAME/ROOF | D20: Structural Steel-Parking | F20: 84577 | G20: -24000 | H20: =F20+G20 -> 60577 | P20: =1706.9+3372.5 -> 5079.4 | Q20: =SUM(I20:P20) -> 5079.4 | R20: =Q20/H20 -> 0.083850306 | S20: =H20-Q20 -> 55497.6 | V20: =S20 -> 55497.6 | W20: 17699.18 | X20: 3550
B21: 012 | C21: FRAME/ROOF | D21: All other Steel Features | F21: 623901.14 | G21: -221107.65 | H21: =F21+G21 -> 402793.49 | I21: 15311.37 | J21: 4548.58 | K21: =352.1+310.68+2916.45+523.7+1048.15+786.03+89.44+7191.56 -> 13218.11 | M21: 217159.55 | P21: =115752.27 -> 115752.27 | Q21: =SUM(I21:P21) -> 365989.88 | R21: =Q21/H21 -> 0.90862908 | S21: =H21-Q21 -> 36803.61 | V21: =S21 -> 36803.61
B22: 013 | C22: FRAME/ROOF | D22: Garage Door For Trash | F22: 4500 | H22: =F22+G22 -> 4500 | Q22: =SUM(I22:P22) -> 0 | R22: =Q22/H22 -> 0 | S22: =H22-Q22 -> 4500 | V22: =S22 -> 4500
B23: 014 | C23: FRAME/ROOF | D23: Store Front Labor | F23: 7500 | G23: 5053.48 | H23: =F23+G23 -> 12553.48 | J23: 7500 | K23: 5053.48 | Q23: =SUM(I23:P23) -> 12553.48 | R23: =Q23/H23 -> 1 | S23: =H23-Q23 -> 0 | V23: 0
B24: 015 | C24: FRAME/ROOF | D24: Elevator | F24: 70150 | H24: =F24+G24 -> 70150 | P24: 18316.72 | Q24: =SUM(I24:P24) -> 18316.72 | R24: =Q24/H24 -> 0.26110791 | S24: =H24-Q24 -> 51833.28 | V24: =S24 -> 51833.28
B25: 016 | C25: FRAME/ROOF | D25: HM Door Labor | F25: 52475 | G25: -19908.96 | H25: =F25+G25 -> 32566.04 | K25: 1500 | N25: 20015.96 | O25: 10964.84 | P25: 39584.35 | Q25: =SUM(I25:P25) -> 72065.15 | R25: =Q25/H25 -> 2.2128926 | S25: =H25-Q25 -> -39499.11 | X25: 17364.5
B26: 017 | C26: MEP TRADES | D26: Plumbing | F26: 524500 | H26: =F26+G26 -> 524500 | I26: 60000 | K26: 124504.85 | L26: 45610.81 | M26: 72610.06 | N26: 38780 | O26: 39955 | P26: 60080 | Q26: =SUM(I26:P26) -> 441540.72 | R26: =Q26/H26 -> 0.84183169 | S26: =H26-Q26 -> 82959.28 | V26: =S26 -> 82959.28 | AA26: Needs to match
B27: 018 | C27: MEP TRADES | D27: HVAC | F27: 1244900 | H27: =F27+G27 -> 1244900 | K27: 204250 | L27: 199500 | M27: 309673.4 | N27: 135208.75 | O27: 85500 | P27: =162938.3 -> 162938.3 | Q27: =SUM(I27:P27) -> 1097070.4 | R27: =Q27/H27 -> 0.88125187 | S27: =H27-Q27 -> 147829.55 | V27: =S27 -> 147829.55
B28: 019 | C28: MEP TRADES | D28: Electric | F28: 434737.1 | H28: =F28+G28 -> 434737.1 | J28: 77050.11 | L28: 51300 | M28: 1500 | P28: 118750 | Q28: =SUM(I28:P28) -> 248600.11 | R28: =Q28/H28 -> 0.57184011 | S28: =H28-Q28 -> 186136.99 | V28: =S28 -> 186136.99
B29: 020 | C29: MEP TRADES | D29: 3 Electric Car Station | F29: 37500 | H29: =F29+G29 -> 37500 | Q29: =SUM(I29:P29) -> 0 | R29: =Q29/H29 -> 0 | S29: =H29-Q29 -> 37500 | V29: =S29 -> 37500
B30: 021 | C30: MEP TRADES | D30: Sprinkler System | F30: 168681 | H30: =F30+G30 -> 168681 | J30: 30210.79 | K30: 44259.74 | L30: 15466 | N30: 1406 | P30: 1406 | Q30: =SUM(I30:P30) -> 92748.53 | R30: =Q30/H30 -> 0.54984574 | S30: =H30-Q30 -> 75932.47 | V30: =S30 -> 75932.47
B31: 022 | C31: MEP TRADES | D31: Fire Caulk | F31: 14750 | H31: =F31+G31 -> 14750 | M31: 423.37 | O31: 3091.66 | P31: =4500+4500 -> 9000 | Q31: =SUM(I31:P31) -> 12515.03 | R31: =Q31/H31 -> 0.84847661 | S31: =H31-Q31 -> 2234.97 | V31: =S31 -> 2234.97
B32: 023 | C32: FINISHES | D32: Gypcrete | F32: 152486 | H32: =F32+G32 -> 152486 | J32: 92390.22 | L32: 15200 | M32: 20900 | N32: 12458.92 | O32: 232.83 | P32: 3135 | Q32: =SUM(I32:P32) -> 144316.97 | R32: =Q32/H32 -> 0.94642767 | S32: =H32-Q32 -> 8169.03 | V32: =S32 -> 8169.03
B33: 024 | C33: FINISHES | D33: Insulation | F33: 222919 | G33: -25000 | H33: =F33+G33 -> 197919 | L33: 117346.28 | M33: 1433.31 | N33: 52303.94 | O33: 12961.87 | Q33: =SUM(I33:P33) -> 184045.4 | R33: =Q33/H33 -> 0.92990264 | S33: =H33-Q33 -> 13873.6 | V33: =S33 -> 13873.6
B34: 025 | C34: FINISHES | D34: Sheetrock | F34: 1467345 | H34: =F34+G34 -> 1467345 | K34: =554084.18-27704.21 -> 526379.97 | L34: 233987.48 | M34: 131595 | O34: =157720+10688.77+66507.92 -> 234916.69 | P34: =5447.61+131594.99 -> 137042.6 | Q34: =SUM(I34:P34) -> 1263921.7 | R34: =Q34/H34 -> 0.86136644 | S34: =H34-Q34 -> 203423.26 | V34: =S34 -> 203423.26
B35: 026 | C35: FINISHES | D35: Finish Materials Misc | F35: 25000 | G35: 146985.68 | H35: =F35+G35 -> 171985.68 | K35: =4867.76+160.24+480.7+9662.93+168 -> 15339.63 | L35: =1081.08+4321.85 -> 5402.93 | M35: =7568.08+75+9977.31+75+75+11568.85+1554.74+2302.59+165.16+75+19908.96+1225.47 -> 54571.16 | N35: =19383.87+102.78+227.03 -> 19713.68 | O35: =986.49+5821.55+3746.54+2650.74+1118.32+739.87+253.55+3746.54+1423.74+3355.33+732.66+4028.15+468.32+5968.05+3044.07+777.47+1082.08+93.25+4750.42+1555.45+1397.53+4009.26+4367.36+3980.7+2547.33+1094.69+4497+6815.99 -> 75052.45 | P35: =27357.55+1968.69+24.56 -> 29350.8 | Q35: =SUM(I35:P35) -> 199430.65 | R35: =Q35/H35 -> 1.1595771 | S35: =H35-Q35 -> -27444.97 | X35: 30000 | Y35: Door rebuild
B36: 027 | C36: FINISHES | D36: Finish Labor | F36: 189135 | G36: -50313.72 | H36: =F36+G36 -> 138821.28 | K36: =13552 -> 13552 | L36: =6024.25+11275.97+48652.42 -> 65952.64 | M36: =685.2+16113.15 -> 16798.35 | O36: =38930.67 -> 38930.67 | P36: =23257.27 -> 23257.27 | Q36: =SUM(I36:P36) -> 158490.93 | R36: =Q36/H36 -> 1.1416905 | S36: =H36-Q36 -> -19669.65 | V36: =S36 -> -19669.65 | X36: 31000 | Y36: Door rebuild
B37: 028 | C37: FINISHES | D37: Interior Paint | F37: 303668.8 | H37: =F37+G37 -> 303668.8 | L37: 16999.73 | N37: 28686.67 | O37: 90618.32 | P37: 169506.27 | Q37: =SUM(I37:P37) -> 305810.99 | R37: =Q37/H37 -> 1.0070544 | S37: =H37-Q37 -> -2142.19 | V37: =S37 -> -2142.19
B38: 029 | C38: FINISHES | D38: Equipment Cabinets | F38: 6000 | H38: =F38+G38 -> 6000 | Q38: =SUM(I38:P38) -> 0 | R38: =Q38/H38 -> 0 | S38: =H38-Q38 -> 6000 | V38: =S38 -> 6000
B39: 030 | C39: FINISHES | D39: Garage Doors | F39: 14081.4 | H39: =F39+G39 -> 14081.4 | P39: =5089.74+10728.37 -> 15818.11 | Q39: =SUM(I39:P39) -> 15818.11 | R39: =Q39/H39 -> 1.1233336 | S39: =H39-Q39 -> -1736.71 | V39: =S39 -> -1736.71 | X39: 3000
B40: 031 | C40: FINISHES | D40: Floor Prep | F40: 10000 | H40: =F40+G40 -> 10000 | P40: 3673.39 | Q40: =SUM(I40:P40) -> 3673.39 | R40: =Q40/H40 -> 0.367339 | S40: =H40-Q40 -> 6326.61 | V40: =S40 -> 6326.61
B41: 032 | C41: FINISHES | D41: Hardware & Install Labor | F41: 65000 | H41: =F41+G41 -> 65000 | N41: 6806.48 | O41: =847.44+245+7783.6 -> 8876.04 | P41: 859.58 | Q41: =SUM(I41:P41) -> 16542.1 | R41: =Q41/H41 -> 0.25449385 | S41: =H41-Q41 -> 48457.9 | V41: =S41 -> 48457.9 | X41: 19065.45 | Y41: Door rebuild
B42: 033 | C42: FINISHES | D42: Fire Extinguishers | F42: 7850 | H42: =F42+G42 -> 7850 | P42: 4811.75 | Q42: =SUM(I42:P42) -> 4811.75 | R42: =Q42/H42 -> 0.61296178 | S42: =H42-Q42 -> 3038.25 | V42: =S42 -> 3038.25
B43: 034 | C43: FINISHES | D43: Mirrors | F43: 24750 | G43: -15000 | H43: =F43+G43 -> 9750 | P43: 6051.5 | Q43: =SUM(I43:P43) -> 6051.5 | R43: =Q43/H43 -> 0.62066667 | S43: =H43-Q43 -> 3698.5 | V43: =S43 -> 3698.5
B44: 035 | C44: FINISHES | D44: Flooring,Wall Tile M&L | F44: 340975 | H44: =F44+G44 -> 340975 | L44: 99384 | M44: 13764.08 | N44: 17929.49 | O44: 40993.65 | P44: =86933.77 -> 86933.77 | Q44: =SUM(I44:P44) -> 259004.99 | R44: =Q44/H44 -> 0.75960111 | S44: =H44-Q44 -> 81970.01 | V44: =S44 -> 81970.01
B45: 036 | C45: EXTERIORS & MISC | D45: Brick | F45: 342000 | G45: 9500 | H45: =F45+G45 -> 351500 | K45: 95000 | L45: 95000 | M45: 66500 | O45: 95000 | P45: =76000+5429.33 -> 81429.33 | Q45: =SUM(I45:P45) -> 432929.33 | R45: =Q45/H45 -> 1.2316624 | S45: =H45-Q45 -> -81429.33 | X45: 98500 | Y45: Difference between budget & contract amount
...

Sheet Future Costs
B5: Subs
B6: Fortified | D6: Corbin
A7: Ignore first CO | B7: Fox and Hound
A8: Will cost a bit more | B8: Landscaping
A9: Go with contract amount | B9: TK
A10: Look into rubber base | B10: Poulson | D10: Corbin
B11: Cleaners | D11: Corbin
A12: Add paint bills into cost & do a deduct on fox & hound | B12: PPC
B13: My Roof
B14: Lara and Sons
B15: Korey
B16: Sunrise Elite
B17: Douggie Fresh
B18: Select Specialties
B19: Toilets
B20: Dumpsters
B21: Shed
B22: Security Cameras
B23: Lock up at night security
B24: Equipment For cabients
... B41: Abrams
